Workbook

Sheet Юнит-экономика
A1: ЮНИТ-ЭКОНОМИКА · Персональная пицца 22 см · B2B СПб
A2: ■ Синий = вводная цифра (можно менять) ■ Чёрный = формула
A3: Статья | B3: Маргарита | C3: Пепперони | D3: С грибами | E3: Средняя (mix) | F3: Комментарий
A4: A. СЕБЕСТОИМОСТЬ ИНГРЕДИЕНТОВ (руб./шт.)
A5: Тесто (мука, вода, дрожжи, соль, масло) | B5: 22 | C5: 22 | D5: 22 | F5: Длительная ферментация 24–48 ч, российская мука
A6: Томатный соус | B6: 10 | C6: 10 | D6: 10 | F6: Пассата / томаты в собственном соку
A7: Сыр моцарелла | B7: 28 | C7: 28 | D7: 28 | F7: Российский производитель
A8: Пепперони (колбаса) | B8: 0 | C8: 40 | D8: 0 | F8: Мясной компонент → Меркурий
A9: Грибы шампиньоны | B9: 0 | C9: 0 | D9: 23 | F9: Свежие или маринованные
A10: Оливковое масло, специи, базилик | B10: 12 | C10: 6 | D10: 6 | F10: Финишная отделка
A11: Доля в продажах (mix %) | B11: 0.4 | C11: 0.4 | D11: 0.2
A12: ИТОГО: себестоимость ингредиентов | B12: =SUM(B5:B10) -> 72 | C12: =SUM(C5:C10) -> 106 | D12: =SUM(D5:D10) -> 89 | E12: =B12*B11+C12*C11+D12*D11 -> 89 | F12: Взвешенная по mix (40/40/20)
A13: B. ПОЛНАЯ СЕБЕСТОИМОСТЬ ЕДИНИЦЫ (руб./шт.)
A14: Ингредиенты | B14: =B12 -> 72 | C14: =C12 -> 106 | D14: =D12 -> 89 | E14: =E12 -> 89 | F14: Из раздела А
A15: Упаковка (коробка, плёнка, стикер) | B15: 10 | C15: 10 | D15: 10 | E15: =B15*B11+C15*C11+D15*D11 -> 10 | F15: Средняя, зависит от тиража
A16: Брак и производственные потери 6% | B16: =B12*0.06 -> 4.32 | C16: =C12*0.06 -> 6.36 | D16: =D12*0.06 -> 5.34 | E16: =E12*0.06 -> 5.34 | F16: % от себестоимости ингредиентов
A17: Электроэнергия, вода, расходники | B17: 4 | C17: 4 | D17: 4 | E17: =B17*B11+C17*C11+D17*D11 -> 4 | F17: Расчётная оценка
A18: Амортизация мелкого инвентаря | B18: 2 | C18: 2 | D18: 2 | E18: =B18*B11+C18*C11+D18*D11 -> 2 | F18: Весы, инструмент
A19: ИТОГО: полная себестоимость (COGS) | B19: =SUM(B14:B18) -> 92.32 | C19: =SUM(C14:C18) -> 128.36 | D19: =SUM(D14:D18) -> 110.34 | E19: =SUM(E14:E18) -> 110.34
A20: C. ЦЕНООБРАЗОВАНИЕ И МАРЖА
A21: Оптовая цена B2B (руб./шт.) | B21: 270 | C21: 270 | D21: 270 | E21: =B21*B11+C21*C11+D21*D11 -> 270 | F21: Единая цена для всех позиций
A22: Валовая маржа (руб./шт.) | B22: =B21-B19 -> 177.68 | C22: =C21-C19 -> 141.64 | D22: =D21-D19 -> 159.66 | E22: =E21-E19 -> 159.66 | F22: Цена − COGS
A23: Валовая маржинальность (%) | B23: =B22/B21 -> 0.65807407 | C23: =C22/C21 -> 0.52459259 | D23: =D22/D21 -> 0.59133333 | E23: =E22/E21 -> 0.59133333 | F23: Маржа / Цена
A24: Наценка заведения x2,3 | B24: =B21*2.3 -> 621 | C24: =C21*2.3 -> 621 | D24: =D21*2.3 -> 621 | E24: =E21*2.3 -> 621 | F24: Цена в меню бара
A25: Наценка заведения x2,5 | B25: =B21*2.5 -> 675 | C25: =C21*2.5 -> 675 | D25: =D21*2.5 -> 675 | E25: =E21*2.5 -> 675 | F25: Цена в меню (оптимистично)
A26: D. ТОЧКА БЕЗУБЫТОЧНОСТИ (партнёрская модель, аренда = 0)
A27: Постоянные расходы в месяц (руб.) | E27: 10000 | F27: Прочие расходы; аренда = 0 (партнёр)
A28: Средняя маржа с пиццы (руб./шт.) | E28: =E22 -> 159.66 | F28: Из строки «Валовая маржа», средняя
A29: ТБУ: штук в месяц | E29: =ROUNDUP(E27/E28,0) -> 63 | F29: Постоянные / Средняя маржа
A30: ТБУ: клиентов при заказе 43 шт./мес. | E30: =ROUNDUP(E29/43,0) -> 2 | F30: Штук ÷ 43
A31: ТБУ: выручка в месяц (руб.) | E31: =E29*E21 -> 17010 | F31: Штук × Оптовая цена
A32: E. ЭКОНОМИКА ОДНОГО B2B-КЛИЕНТА (в месяц)
A33: Заказов в неделю (пицц) | E33: 10 | F33: Средний клиент
A34: Заказов в месяц (пицц) | E34: =E33*4.3 -> 43 | F34: ×4,3 недели
A35: Выручка от клиента (руб./мес.) | E35: =E34*E21 -> 11610 | F35: Штук × Оптовая цена
A36: Переменные затраты (руб./мес.) | E36: =E34*E19 -> 4744.62 | F36: Штук × COGS средняя
A37: Маржа от клиента (руб./мес.) | E37: =E35-E36 -> 6865.38 | F37: Выручка − Затраты
A38: F. БЫСТРЫЙ P&L: ЧТО МЕНЯЕТСЯ ПРИ РОСТЕ ЧИСЛА КЛИЕНТОВ
A39: Клиентов | B39: Пицц/мес. | C39: Выручка | D39: COGS | E39: Вал. маржа | F39: Чистая маржа*
A40: 2 | B40: =A40*E34 -> 86 | C40: =B40*E21 -> 23220 | D40: =B40*E19 -> 9489.24 | E40: =C40-D40 -> 13730.76 | F40: =(E40-E27)*(1-0.15) -> 3171.146
...

Sheet Допущения
A1: ДОПУЩЕНИЯ И ИСТОЧНИКИ
A2: ПРОДУКТ
A3: Диаметр пиццы | B3: 22 см | C3: Персональный формат для B2B
A4: Метод замораживания | B4: Шоковая заморозка | C4: Оборудование партнёра
A5: Срок хранения | B5: 3–6 месяцев | C5: При −18°С
A6: Время приготовления у клиента | B6: 5–8 мин | C6: Конвекционная печь 220–230°С
A8: ИНГРЕДИЕНТЫ
A9: Мука | B9: Российская (Макфа, Алейка) | C9: Замена итальянской → экономия ~15 руб./шт.
A10: Сыр моцарелла | B10: Российский производитель | C10: Оптовая закупка
A11: Процент брака | B11: 6% | C11: Консервативная оценка для нового производства
A13: ПРОДАЖИ
A14: Оптовая цена (все SKU) | B14: 250 руб./шт. | C14: Единая цена; пересмотр с 6 мес.
A15: Средний заказ клиента | B15: 10 пицц/неделю | C15: 43 шт./месяц
A16: Mix продаж (Маргарита / Пепперони / Грибы) | B16: 40% / 40% / 20% | C16: Оценка на старте
A17: Наценка заведения в меню | B17: ×2,3–2,5 | C17: Цена гостя ~575–625 руб.
A19: ОПЕРАЦИОННЫЕ РАСХОДЫ (партнёрская модель)
A20: Аренда производственного цеха | B20: 0 руб./мес. | C20: Покрывается партнёром-арендодателем
A21: Логистика | B21: 0–5 000 руб./мес. | C21: Инфраструктура партнёра; min расходы на первые доставки
A22: Прочие расходы | B22: 10 000 руб./мес. | C22: Связь, расходники, непредвиденное
A24: НАЛОГИ
A25: Система налогообложения | B25: УСН 15% (доходы минус расходы)
A26: Страховые взносы ИП (фиксированные) | B26: ~49 500 руб./год | C26: 2025 год, при доходах до 300 тыс.

Sheet P&L Детальный
A1: P&L ДЕТАЛЬНЫЙ · БАЗОВЫЙ СЦЕНАРИЙ ОПТИМИЗИРОВАННЫЙ · 12 месяцев
A2: ✦ Старт с 5 клиентов | транспорт 350 руб./клиент | помощник при 10 кл. | заказ растёт до 25 пицц/нед. с мес.6 | аренды нет
A3: ■ Синий = вводная цифра ■ Чёрный = формула ■ Зелёный = ссылка на «Юнит-экономику»
A4: ▌ ДОПУЩЕНИЯ ОПТИМИЗИРОВАННОГО СЦЕНАРИЯ
A5: Статья | B5: Месяц 1 | C5: Месяц 2 | D5: Месяц 3 | E5: Месяц 4 | F5: Месяц 5 | G5: Месяц 6 | H5: Месяц 7 | I5: Месяц 8 | J5: Месяц 9 | K5: Месяц 10 | L5: Месяц 11 | M5: Месяц 12 | N5: ИТОГО год
A6: Активных клиентов (шт.) | B6: 5 | C6: 7 | D6: 8 | E6: 10 | F6: 12 | G6: 13 | H6: 15 | I6: 16 | J6: 18 | K6: 20 | L6: 22 | M6: 24 | N6: 170
A7: Пицц на клиента в месяц (мес.1–5: 65 | мес.6+: 108) | B7: 65 | C7: 65 | D7: 65 | E7: 65 | F7: 65 | G7: 108 | H7: 108 | I7: 108 | J7: 108 | K7: 108 | L7: 108 | M7: 108 | N7: 1081
A8: Пицц произведено в месяц (шт.) | B8: 325 | C8: 455 | D8: 520 | E8: 650 | F8: 780 | G8: 1404 | H8: 1620 | I8: 1728 | J8: 1944 | K8: 2160 | L8: 2376 | M8: 2592 | N8: 16554
A9: → Маргарита (40%) | B9: 130 | C9: 182 | D9: 208 | E9: 260 | F9: 312 | G9: 561.6 | H9: 648 | I9: 691.2 | J9: 777.6 | K9: 864 | L9: 950.4 | M9: 1036.8 | N9: 6621.6
A10: → Пепперони (40%) | B10: 130 | C10: 182 | D10: 208 | E10: 260 | F10: 312 | G10: 561.6 | H10: 648 | I10: 691.2 | J10: 777.6 | K10: 864 | L10: 950.4 | M10: 1036.8 | N10: 6621.6
A11: → С грибами (20%) | B11: 65 | C11: 91 | D11: 104 | E11: 130 | F11: 156 | G11: 280.8 | H11: 324 | I11: 345.6 | J11: 388.8 | K11: 432 | L11: 475.2 | M11: 518.4 | N11: 3310.8
A13: ▌ ВЫРУЧКА (цена 270 руб./шт.)
A14: Выручка: Маргарита | B14: 35100 | C14: 49140 | D14: 56160 | E14: 70200 | F14: 84240 | G14: 151632 | H14: 174960 | I14: 186624 | J14: 209952 | K14: 233280 | L14: 256608 | M14: 279936 | N14: 1787832
A15: Выручка: Пепперони | B15: 35100 | C15: 49140 | D15: 56160 | E15: 70200 | F15: 84240 | G15: 151632 | H15: 174960 | I15: 186624 | J15: 209952 | K15: 233280 | L15: 256608 | M15: 279936 | N15: 1787832
A16: Выручка: С грибами | B16: 17550 | C16: 24570 | D16: 28080 | E16: 35100 | F16: 42120 | G16: 75816 | H16: 87480 | I16: 93312 | J16: 104976 | K16: 116640 | L16: 128304 | M16: 139968 | N16: 893916
A17: ИТОГО ВЫРУЧКА | B17: 87750 | C17: 122850 | D17: 140400 | E17: 175500 | F17: 210600 | G17: 379080 | H17: 437400 | I17: 466560 | J17: 524880 | K17: 583200 | L17: 641520 | M17: 699840 | N17: 4469580
A19: ▌ ПЕРЕМЕННЫЕ ЗАТРАТЫ — COGS (упаковка 10 руб./шт.)
A20: Ингредиенты и брак по SKU:
A21: Ингредиенты: Маргарита | B21: 9360 | C21: 13104 | D21: 14976 | E21: 18720 | F21: 22464 | G21: 40435.2 | H21: 46656 | I21: 49766.4 | J21: 55987.2 | K21: 62208 | L21: 68428.8 | M21: 74649.6 | N21: 476755.2
A22: Брак 6%: Маргарита | B22: 561.6 | C22: 786.24 | D22: 898.56 | E22: 1123.2 | F22: 1347.84 | G22: 2426.11 | H22: 2799.36 | I22: 2985.98 | J22: 3359.23 | K22: 3732.48 | L22: 4105.73 | M22: 4478.98 | N22: 28605.31
A23: Ингредиенты: Пепперони | B23: 13780 | C23: 19292 | D23: 22048 | E23: 27560 | F23: 33072 | G23: 59529.6 | H23: 68688 | I23: 73267.2 | J23: 82425.6 | K23: 91584 | L23: 100742.4 | M23: 109900.8 | N23: 701889.6
A24: Брак 6%: Пепперони | B24: 826.8 | C24: 1157.52 | D24: 1322.88 | E24: 1653.6 | F24: 1984.32 | G24: 3571.78 | H24: 4121.28 | I24: 4396.03 | J24: 4945.54 | K24: 5495.04 | L24: 6044.54 | M24: 6594.05 | N24: 42113.38
A25: Ингредиенты: С грибами | B25: 5785 | C25: 8099 | D25: 9256 | E25: 11570 | F25: 13884 | G25: 24991.2 | H25: 28836 | I25: 30758.4 | J25: 34603.2 | K25: 38448 | L25: 42292.8 | M25: 46137.6 | N25: 294661.2
A26: Брак 6%: С грибами | B26: 347.1 | C26: 485.94 | D26: 555.36 | E26: 694.2 | F26: 833.04 | G26: 1499.47 | H26: 1730.16 | I26: 1845.5 | J26: 2076.19 | K26: 2306.88 | L26: 2537.57 | M26: 2768.26 | N26: 17679.67
A28: Упаковка (10 руб./шт. — оптовый тираж 500+) | B28: 3250 | C28: 4550 | D28: 5200 | E28: 6500 | F28: 7800 | G28: 14040 | H28: 16200 | I28: 17280 | J28: 19440 | K28: 21600 | L28: 23760 | M28: 25920 | N28: 165540
A29: Электроэнергия, вода, расходники | B29: 1300 | C29: 1820 | D29: 2080 | E29: 2600 | F29: 3120 | G29: 5616 | H29: 6480 | I29: 6912 | J29: 7776 | K29: 8640 | L29: 9504 | M29: 10368 | N29: 66216
A30: Амортизация мелкого инвентаря | B30: 650 | C30: 910 | D30: 1040 | E30: 1300 | F30: 1560 | G30: 2808 | H30: 3240 | I30: 3456 | J30: 3888 | K30: 4320 | L30: 4752 | M30: 5184 | N30: 33108
A31: ИТОГО ПЕРЕМЕННЫЕ ЗАТРАТЫ (COGS) | B31: 35860.5 | C31: 50204.7 | D31: 57376.8 | E31: 71721 | F31: 86065.2 | G31: 154917.36 | H31: 178750.8 | I31: 190667.52 | J31: 214500.96 | K31: 238334.4 | L31: 262167.84 | M31: 286001.28 | N31: 1826568.4
A33: ВАЛОВАЯ МАРЖА | B33: 51889.5 | C33: 72645.3 | D33: 83023.2 | E33: 103779 | F33: 124534.8 | G33: 224162.64 | H33: 258649.2 | I33: 275892.48 | J33: 310379.04 | K33: 344865.6 | L33: 379352.16 | M33: 413838.72 | N33: 2643011.6
A34: Маржинальность (%) | B34: 0.591333 | C34: 0.591333 | D34: 0.591333 | E34: 0.591333 | F34: 0.591333 | G34: 0.591333 | H34: 0.591333 | I34: 0.591333 | J34: 0.591333 | K34: 0.591333 | L34: 0.591333 | M34: 0.591333 | N34: 0.591333
A36: ▌ ПОСТОЯННЫЕ РАСХОДЫ (стартовые 170 000 руб. — в месяц 0, вне P&L)
A37: Аренда производственного цеха ← 0 (покрывает партнёр) | B37: 0 | C37: 0 | D37: 0 | E37: 0 | F37: 0 | G37: 0 | H37: 0 | I37: 0 | J37: 0 | K37: 0 | L37: 0 | M37: 0 | N37: 0
A38: Логистика (350 руб. × кол-во клиентов) | B38: 1750 | C38: 2450 | D38: 2800 | E38: 3500 | F38: 4200 | G38: 4550 | H38: 5250 | I38: 5600 | J38: 6300 | K38: 7000 | L38: 7700 | M38: 8400 | N38: 59500
A39: Маркетинг (Telegram, визитки, дегустации) | B39: 5000 | C39: 5000 | D39: 3000 | E39: 3000 | F39: 3000 | G39: 3000 | H39: 2000 | I39: 2000 | J39: 2000 | K39: 2000 | L39: 2000 | M39: 2000 | N39: 34000
A40: Связь, подписки, канцелярия | B40: 2000 | C40: 2000 | D40: 2000 | E40: 2000 | F40: 2000 | G40: 2000 | H40: 2000 | I40: 2000 | J40: 2000 | K40: 2000 | L40: 2000 | M40: 2000 | N40: 24000
A41: Прочие непредвиденные | B41: 5000 | C41: 5000 | D41: 5000 | E41: 5000 | F41: 5000 | G41: 5000 | H41: 5000 | I41: 5000 | J41: 5000 | K41: 5000 | L41: 5000 | M41: 5000 | N41: 60000
A43: Фонд оплаты труда (ФОТ):
A44: ЗП помощника (при ≥10 клиентах: 25 000 руб.) | B44: 0 | C44: 0 | D44: 0 | E44: 25000 | F44: 25000 | G44: 25000 | H44: 25000 | I44: 25000 | J44: 25000 | K44: 25000 | L44: 25000 | M44: 25000 | N44: 225000
A45: ЗП основателя (с месяца 8 при достижении триггера) | B45: 0 | C45: 0 | D45: 0 | E45: 0 | F45: 0 | G45: 0 | H45: 0 | I45: 30000 | J45: 30000 | K45: 30000 | L45: 30000 | M45: 30000 | N45: 150000
A46: Страховые взносы на ФОТ (30%) | B46: 0 | C46: 0 | D46: 0 | E46: 7500 | F46: 7500 | G46: 7500 | H46: 7500 | I46: 16500 | J46: 16500 | K46: 16500 | L46: 16500 | M46: 16500 | N46: 112500
...

Sheet Cash Flow
A1: CASH FLOW (ДВИЖЕНИЕ ДЕНЕЖНЫХ СРЕДСТВ) · Базовый сценарий · 12 месяцев
A2: ⚠ B2B-специфика учтена: отсрочка оплаты клиентами ~14 дней (50% выручки месяца приходит в следующем месяце) · Ингредиенты закупаются авансом 50% · УСН платится поквартально
A3: ■ Синий = вводная цифра ■ Чёрный = формула ■ Зелёный = ссылка на P&L Детальный
A4: ▌ ДОПУЩЕНИЯ CASH FLOW
A5: Статья | B5: Месяц 0 (до старта) | C5: М1 | D5: М2 | E5: М3 | F5: М4 | G5: М5 | H5: М6 | I5: М7 | J5: М8 | K5: М9 | L5: М10 | M5: М11 | N5: М12 | O5: ИТОГО
A6: Инвестиция партнёра-арендодателя (разово, мес. 0) | B6: 350000 | C6: 0 | D6: 0 | E6: 0 | F6: 0 | G6: 0 | H6: 0 | I6: 0 | J6: 0 | K6: 0 | L6: 0 | M6: 0 | N6: 0 | O6: 0
A7: Отсрочка оплаты B2B-клиентами: 50% выручки текущего месяца поступает в текущем, 50% — в следующем. Среднее: отсрочка ~14 дней.
A8: Ингредиенты: 50% стоимости COGS закупается авансом (месяц текущий), 50% — по факту. Упрощение: всё COGS платится в месяце производства.
A9: УСН: авансовые платежи ежеквартально (мес. 4, 7, 10), итоговый платёж в мес. 12 (за год).
A11: ▌ ПОСТУПЛЕНИЯ ДЕНЕЖНЫХ СРЕДСТВ
A12: Инвестиция партнёра | B12: 350000 | C12: 0 | D12: 0 | E12: 0 | F12: 0 | G12: 0 | H12: 0 | I12: 0 | J12: 0 | K12: 0 | L12: 0 | M12: 0 | N12: 0 | O12: =SUM(B11:N11) -> 0
A13: Поступления от клиентов (с отсрочкой 14 дней: 50%+50%) | B13: 0 | C13: =ROUND('P&L Детальный'!B17*0.5, 0) -> 43875 | D13: =ROUND('P&L Детальный'!C17*0.5+'P&L Детальный'!B17*0.5, 0) -> 105300 | E13: =ROUND('P&L Детальный'!D17*0.5+'P&L Детальный'!C17*0.5, 0) -> 131625 | F13: =ROUND('P&L Детальный'!E17*0.5+'P&L Детальный'!D17*0.5, 0) -> 157950 | G13: =ROUND('P&L Детальный'!F17*0.5+'P&L Детальный'!E17*0.5, 0) -> 193050 | H13: =ROUND('P&L Детальный'!G17*0.5+'P&L Детальный'!F17*0.5, 0) -> 294840 | I13: =ROUND('P&L Детальный'!H17*0.5+'P&L Детальный'!G17*0.5, 0) -> 408240 | J13: =ROUND('P&L Детальный'!I17*0.5+'P&L Детальный'!H17*0.5, 0) -> 451980 | K13: =ROUND('P&L Детальный'!J17*0.5+'P&L Детальный'!I17*0.5, 0) -> 495720 | ... N13: =ROUND('P&L Детальный'!M17*0.5+'P&L Детальный'!L17*0.5, 0) -> 670680 | O13: =SUM(C13:N13) -> 4119660
A14: ↑ 50% выручки декабря (~92 000 руб.) поступит в январе следующего года — дебиторская задолженность
A15: ИТОГО ПОСТУПЛЕНИЯ | B15: =B12+B13 -> 350000 | C15: =C12+C13 -> 43875 | D15: =D12+D13 -> 105300 | E15: =E12+E13 -> 131625 | F15: =F12+F13 -> 157950 | G15: =G12+G13 -> 193050 | H15: =H12+H13 -> 294840 | I15: =I12+I13 -> 408240 | ... N15: =N12+N13 -> 670680 | O15: =SUM(B15:N15) -> 4469660
A17: ▌ ВЫПЛАТЫ ДЕНЕЖНЫХ СРЕДСТВ
A18: Стартовые расходы (мес. 0): документы, обучение, закупка, упаковка, оборудование | B18: 170000 | C18: 0 | D18: 0 | E18: 0 | F18: 0 | G18: 0 | H18: 0 | I18: 0 | J18: 0 | K18: 0 | L18: 0 | M18: 0 | N18: 0 | O18: 170000
A20: Б. Оплата переменных затрат (ингредиенты, упаковка, прочее COGS):
A21: Оплата COGS (ингредиенты, упаковка, брак, электричество) | B21: 0 | C21: ='P&L Детальный'!B31 -> 35860.5 | D21: ='P&L Детальный'!C31 -> 50204.7 | E21: ='P&L Детальный'!D31 -> 57376.8 | F21: ='P&L Детальный'!E31 -> 71721 | G21: ='P&L Детальный'!F31 -> 86065.2 | H21: ='P&L Детальный'!G31 -> 154917.36 | I21: ='P&L Детальный'!H31 -> 178750.8 | J21: ='P&L Детальный'!I31 -> 190667.52 | ... N21: ='P&L Детальный'!M31 -> 286001.28 | O21: =SUM(C21:N21) -> 1826568.4
A23: В. Постоянные платежи (ежемесячно):
A24: Логистика | B24: 0 | C24: ='P&L Детальный'!B38 -> 1750 | D24: ='P&L Детальный'!C38 -> 2450 | E24: ='P&L Детальный'!D38 -> 2800 | F24: ='P&L Детальный'!E38 -> 3500 | G24: ='P&L Детальный'!F38 -> 4200 | H24: ='P&L Детальный'!G38 -> 4550 | I24: ='P&L Детальный'!H38 -> 5250 | J24: ='P&L Детальный'!I38 -> 5600 | ... N24: ='P&L Детальный'!M38 -> 8400 | O24: =SUM(C24:N24) -> 59500
A25: Маркетинг | B25: 0 | C25: ='P&L Детальный'!B39 -> 5000 | D25: ='P&L Детальный'!C39 -> 5000 | E25: ='P&L Детальный'!D39 -> 3000 | F25: ='P&L Детальный'!E39 -> 3000 | G25: ='P&L Детальный'!F39 -> 3000 | H25: ='P&L Детальный'!G39 -> 3000 | I25: ='P&L Детальный'!H39 -> 2000 | J25: ='P&L Детальный'!I39 -> 2000 | ... N25: ='P&L Детальный'!M39 -> 2000 | O25: =SUM(C25:N25) -> 34000
A26: Связь, подписки, канцелярия | B26: 0 | C26: ='P&L Детальный'!B40 -> 2000 | D26: ='P&L Детальный'!C40 -> 2000 | E26: ='P&L Детальный'!D40 -> 2000 | F26: ='P&L Детальный'!E40 -> 2000 | G26: ='P&L Детальный'!F40 -> 2000 | H26: ='P&L Детальный'!G40 -> 2000 | I26: ='P&L Детальный'!H40 -> 2000 | J26: ='P&L Детальный'!I40 -> 2000 | ... N26: ='P&L Детальный'!M40 -> 2000 | O26: =SUM(C26:N26) -> 24000
A27: Прочие непредвиденные | B27: 0 | C27: ='P&L Детальный'!B41 -> 5000 | D27: ='P&L Детальный'!C41 -> 5000 | E27: ='P&L Детальный'!D41 -> 5000 | F27: ='P&L Детальный'!E41 -> 5000 | G27: ='P&L Детальный'!F41 -> 5000 | H27: ='P&L Детальный'!G41 -> 5000 | I27: ='P&L Детальный'!H41 -> 5000 | J27: ='P&L Детальный'!I41 -> 5000 | ... N27: ='P&L Детальный'!M41 -> 5000 | O27: =SUM(C27:N27) -> 60000
A28: ЗП помощника | B28: 0 | C28: ='P&L Детальный'!B44 -> 0 | D28: ='P&L Детальный'!C44 -> 0 | E28: ='P&L Детальный'!D44 -> 0 | F28: ='P&L Детальный'!E44 -> 25000 | G28: ='P&L Детальный'!F44 -> 25000 | H28: ='P&L Детальный'!G44 -> 25000 | I28: ='P&L Детальный'!H44 -> 25000 | J28: ='P&L Детальный'!I44 -> 25000 | ... N28: ='P&L Детальный'!M44 -> 25000 | O28: =SUM(C28:N28) -> 225000
A29: ЗП основателя | B29: 0 | C29: ='P&L Детальный'!B45 -> 0 | D29: ='P&L Детальный'!C45 -> 0 | E29: ='P&L Детальный'!D45 -> 0 | F29: ='P&L Детальный'!E45 -> 0 | G29: ='P&L Детальный'!F45 -> 0 | H29: ='P&L Детальный'!G45 -> 0 | I29: ='P&L Детальный'!H45 -> 0 | J29: ='P&L Детальный'!I45 -> 30000 | ... N29: ='P&L Детальный'!M45 -> 30000 | O29: =SUM(C29:N29) -> 150000
A30: Страховые взносы (30% от ФОТ) | B30: 0 | C30: ='P&L Детальный'!B46 -> 0 | D30: ='P&L Детальный'!C46 -> 0 | E30: ='P&L Детальный'!D46 -> 0 | F30: ='P&L Детальный'!E46 -> 7500 | G30: ='P&L Детальный'!F46 -> 7500 | H30: ='P&L Детальный'!G46 -> 7500 | I30: ='P&L Детальный'!H46 -> 7500 | J30: ='P&L Детальный'!I46 -> 16500 | ... N30: ='P&L Детальный'!M46 -> 16500 | O30: =SUM(C30:N30) -> 112500
A31: Итого постоянные платежи | B31: =B24+B25+B26+B27+B28+B29+B30 -> 0 | C31: =C24+C25+C26+C27+C28+C29+C30 -> 13750 | D31: =D24+D25+D26+D27+D28+D29+D30 -> 14450 | E31: =E24+E25+E26+E27+E28+E29+E30 -> 12800 | F31: =F24+F25+F26+F27+F28+F29+F30 -> 46000 | G31: =G24+G25+G26+G27+G28+G29+G30 -> 46700 | H31: =H24+H25+H26+H27+H28+H29+H30 -> 47050 | I31: =I24+I25+I26+I27+I28+I29+I30 -> 46750 | ... N31: =N24+N25+N26+N27+N28+N29+N30 -> 88900 | O31: =SUM(B31:N31) -> 665000
A33: Г. Налоговые платежи (УСН — поквартально: мес. 4, 7, 10, 12):
A34: УСН 15% — квартальные авансовые платежи | B34: 0 | C34: 0 | D34: 0 | E34: 0 | F34: =ROUND(('P&L Детальный'!C56+'P&L Детальный'!D56+'P&L Детальный'!E56),0) -> 27929 | G34: 0 | H34: 0 | I34: =ROUND(('P&L Детальный'!F56+'P&L Детальный'!G56+'P&L Детальный'!H56),0) -> 70027 | J34: 0 | K34: 0 | L34: =ROUND(('P&L Детальный'!I56+'P&L Детальный'!J56+'P&L Детальный'!K56),0) -> 100611 | M34: 0 | N34: =ROUND(('P&L Детальный'!L56+'P&L Детальный'!M56+'P&L Детальный'!N56),0) -> 389116 | O34: =SUM(C34:N34) -> 587683
A35: Итого налоговые платежи | B35: =B34 -> 0 | C35: =C34 -> 0 | D35: =D34 -> 0 | E35: =E34 -> 0 | F35: =F34 -> 27929 | G35: =G34 -> 0 | H35: =H34 -> 0 | I35: =I34 -> 70027 | ... N35: =N34 -> 389116 | O35: =SUM(B35:N35) -> 587683
A37: ИТОГО ВЫПЛАТЫ | B37: =B18+B21+B31+B35 -> 170000 | C37: =C18+C21+C31+C35 -> 49610.5 | D37: =D18+D21+D31+D35 -> 64654.7 | E37: =E18+E21+E31+E35 -> 70176.8 | F37: =F18+F21+F31+F35 -> 145650 | G37: =G18+G21+G31+G35 -> 132765.2 | H37: =H18+H21+H31+H35 -> 201967.36 | I37: =I18+I21+I31+I35 -> 295527.8 | ... N37: =N18+N21+N31+N35 -> 764017.28 | O37: =SUM(B37:N37) -> 3249251.4
A39: ЧИСТЫЙ ДЕНЕЖНЫЙ ПОТОК ЗА МЕСЯЦ | B39: =B15-B37 -> 180000 | C39: =C15-C37 -> -5735.5 | D39: =D15-D37 -> 40645.3 | E39: =E15-E37 -> 61448.2 | F39: =F15-F37 -> 12300 | G39: =G15-G37 -> 60284.8 | H39: =H15-H37 -> 92872.64 | I39: =I15-I37 -> 112712.2 | ... N39: =N15-N37 -> -93337.28 | O39: =SUM(B39:N39) -> 1220408.6
A41: ▌ ОСТАТОК ДЕНЕЖНЫХ СРЕДСТВ НА СЧЁТЕ
A42: Остаток на конец месяца (накопленный) | B42: =B39 -> 180000 | C42: =B42+C39 -> 174264.5 | D42: =C42+D39 -> 214909.8 | E42: =D42+E39 -> 276358 | F42: =E42+F39 -> 288658 | G42: =F42+G39 -> 348942.8 | H42: =G42+H39 -> 441815.44 | I42: =H42+I39 -> 554527.64 | J42: =I42+J39 -> 729740.12 | ... N42: =M42+N39 -> 1220408.6 | O42: =N42 -> 1220408.6
A43: Минимальный рекомендуемый резерв (2 мес. постоянных расходов) | B43: 30000 | C43: 30000 | D43: 30000 | E43: 40000 | F43: 40000 | G43: 70000 | H43: 70000 | I43: 70000 | J43: 70000 | K43: 70000 | L43: 70000 | M43: 70000 | N43: 70000 | O43: 70000
A44: Запас прочности (остаток − резерв) | B44: 150000 | C44: 104264 | D44: 144910 | E44: 206358 | F44: 221604 | G44: 281889 | H44: 374761 | I44: 510592 | J44: 685804 | K44: 880223 | L44: 1014638 | M44: 1276630 | N44: 1441390 | O44: 1441390
A46: ▌ СВОДКА: КЛЮЧЕВЫЕ ПОКАЗАТЕЛИ ПО МЕСЯЦАМ
A47: Статья | B47: Месяц 0 (до старта) | C47: М1 | D47: М2 | E47: М3 | F47: М4 | G47: М5 | H47: М6 | I47: М7 | J47: М8 | K47: М9 | L47: М10 | M47: М11 | N47: М12 | O47: ИТОГО
A48: Выручка (из P&L) | B48: 0 | C48: 87750 | D48: 122850 | E48: 140400 | F48: 175500 | G48: 210600 | H48: 379080 | I48: 437400 | J48: 466560 | K48: 524880 | L48: 583200 | M48: 641520 | N48: 699840 | O48: =SUM(C48:N48) -> 4469580
A49: Чистая прибыль (из P&L) | B49: 0 | C49: 32418 | D49: 49466 | E49: 59690 | F49: 49112 | G49: 66160 | H49: 150546 | I49: 180114 | J49: 161323 | K49: 190042 | L49: 218761 | M49: 247479 | N49: 276198 | O49: =SUM(C49:N49) -> 1681309
...

Sheet Инвестиции
A1: КАЛЬКУЛЯТОР ИНВЕСТИЦИИ · Что входит и что остаётся (печь и тестомес — у партнёра)
A2: ■ Синий = бюджет (можно менять) ■ Жёлтый = фактическая цена (вводи при покупке) ■ Серый = справочно
A4: ▌ 1. ОБОРУДОВАНИЕ (разовая покупка, собственность ООО)
A5: № | B5: Статья расхода | C5: Категория | D5: Мин, руб. | E5: Макс, руб. | F5: Бюджет, руб. | G5: Факт, руб. | H5: Примечание / источник
A6: 1 | B6: Конвекционная печь для пиццы — есть у партнёра | C6: — не требуется | D6: 0 | E6: 0 | F6: 0 | H6: Stalgast, Bartscher, российские аналоги. Важно: конвекция, до 300°C, таймер. Б/у — от 35 000.
A7: 2 | B7: Тестомес спиральный — есть у партнёра | C7: — не требуется | D7: 0 | E7: 0 | F7: 0 | G7: 0 | H7: Для длительной ферментации критичен объём дежи. Vitek, Gastrorag, Apach — 50–85 тыс. Б/у — от 25 000.
A8: 3 | B8: Лотки для теста (расстойка, ферментация) — комплект 20 шт. | C8: Инвентарь | D8: 4000 | E8: 8000 | F8: 6000 | H8: Пластиковые гастроёмкости GN 1/1 с крышками. ~200–400 руб./шт. × 20 шт.
A9: 4 | B9: Весы кухонные электронные (до 5 кг, точность 1 г) | C9: Инвентарь | D9: 1500 | E9: 3500 | F9: 2500 | H9: Обязательно для стабильного качества. Любой бренд с точностью ±1 г.
A10: 5 | B10: Скалки, разделочные доски, контейнеры, ножи, лопатки | C10: Инвентарь | D10: 3000 | E10: 6000 | F10: 4000 | H10: Базовый инвентарь. Закупка в проф. магазине.
A11: 6 | B11: Пульверизатор, кисти, силиконовые коврики | C11: Инвентарь | D11: 500 | E11: 1500 | F11: 1000 | H11: Финишная отделка, смазка коржей.
A12: ИТОГО: Оборудование и инвентарь | D12: =D6+D7+D8+D9+D10+D11 -> 9000 | E12: =E6+E7+E8+E9+E10+E11 -> 19000 | F12: =F6+F7+F8+F9+F10+F11 -> 13500 | G12: =G6+G7+G8+G9+G10+G11 -> 0
A14: ▌ 2. ПЕРВИЧНАЯ ЗАКУПКА ИНГРЕДИЕНТОВ (начинка — НЕ у арендодателя)
A15: № | B15: Статья расхода | C15: Категория | D15: Мин, руб. | E15: Макс, руб. | F15: Бюджет, руб. | G15: Факт, руб. | H15: Примечание / источник
A16: 7 | B16: Томатный соус / пассата (оптовая закупка ~30 кг) | C16: Ингредиенты | D16: 2400 | E16: 4500 | F16: 3000 | H16: ~80–150 руб./кг оптом. Запас на 300 пицц (первые 3–4 недели работы).
A17: 8 | B17: Моцарелла (оптовая закупка ~15 кг) | C17: Ингредиенты | D17: 5250 | E17: 9000 | F17: 7000 | H17: 350–600 руб./кг оптом. Российские производители: Умалат, Cheese Gallery. Запас на ~500 пицц.
A18: 9 | B18: Пепперони / колбаса (оптовая закупка ~8 кг) | C18: Ингредиенты | D18: 2400 | E18: 4800 | F18: 3500 | H18: 300–600 руб./кг. Нужен ветеринарный сертификат (Меркурий). Запас на ~200 пицц Пепперони.
A19: 10 | B19: Грибы шампиньоны свежие (закупка ~10 кг) | C19: Ингредиенты | D19: 800 | E19: 1500 | F19: 1000 | H19: 80–150 руб./кг оптом. Закупать по мере расхода — срок хранения 5–7 дней.
A20: 11 | B20: Оливковое масло, специи, базилик (стартовый запас) | C20: Ингредиенты | D20: 1500 | E20: 3000 | F20: 2000 | H20: Хранится долго. Закупить сразу на 3–4 месяца.
A21: 12 | B21: Мука, дрожжи, соль, сахар (есть у арендодателя) | C21: Ингредиенты | D21: 0 | E21: 0 | F21: 0 | H21: ✓ Предоставляет партнёр-арендодатель. Зафиксировать в договоре.
A22: ИТОГО: Первичная закупка ингредиентов | D22: =D16+D17+D18+D19+D20+D21 -> 12350 | E22: =E16+E17+E18+E19+E20+E21 -> 22800 | F22: =F16+F17+F18+F19+F20+F21 -> 16500 | G22: =G16+G17+G18+G19+G20+G21 -> 0
A24: ▌ 3. ПРЕДСТАРТОВЫЕ РАСХОДЫ (месяц 0 — до первых продаж)
A25: № | B25: Статья расхода | C25: Категория | D25: Мин, руб. | E25: Макс, руб. | F25: Бюджет, руб. | G25: Факт, руб. | H25: Примечание / источник
A26: 13 | B26: Стажировка у пиццайоло (2–3 недели, обучение технологии заморозки) | C26: Обучение | D26: 10000 | E26: 20000 | F26: 15000 | H26: Рекомендуется именно производство заморозки, не пиццерия. Можно договориться бесплатно за помощь.
A27: 14 | B27: Тестовые партии (50–80 пицц: тесто, заморозка, выпечка у клиентов) | C27: Тест-производство | D27: 8000 | E27: 15000 | F27: 12000 | H27: Тест цикла: замесить → сформировать → заморозить → разморозить → выпечь. Повторить 3–5 раз до стабильного качества.
A28: 15 | B28: Декларация соответствия ТР ТС 021/2011 | C28: Документы | D28: 15000 | E28: 35000 | F28: 25000 | H28: Через аккредитованный орган. Работа на мощностях партнёра снижает стоимость — его площадка уже сертифицирована.
A29: 16 | B29: Разработка и регистрация ТУ (технические условия) | C29: Документы | D29: 10000 | E29: 25000 | F29: 15000 | H29: Можно через партнёра (у него уже есть ТУ на производство). Или отдельно через технолога-консультанта.
A30: 17 | B30: ХАССП базовый уровень (разработка документации) | C30: Документы | D30: 5000 | E30: 15000 | F30: 8000 | H30: Для работы на чужих сертифицированных мощностях — упрощённый вариант. Можно шаблон + доработка.
A31: 18 | B31: Медицинские книжки (основатель + помощник в будущем) | C31: Документы | D31: 1000 | E31: 3000 | F31: 2000 | H31: 1 500–3 000 руб./чел. Обязательно до начала работы.
A32: 19 | B32: Уведомление Роспотребнадзора (подача) | C32: Документы | D32: 0 | E32: 500 | F32: 0 | H32: Госпошлина не взимается. Только время на подачу.
A33: 20 | B33: Регистрация в Меркурий (пепперони — мясной компонент) | C33: Документы | D33: 0 | E33: 5000 | F33: 2000 | H33: Можно через партнёра, у которого уже есть доступ. Или самостоятельно через Россельхознадзор.
A34: 21 | B34: Упаковка: коробки, плёнка, стикеры, этикетки (первый тираж 500 шт.) | C34: Упаковка | D34: 4000 | E34: 7000 | F34: 5000 | H34: Коробка ~6–10 руб./шт. оптом. Стикер + плёнка + этикетка ~4 руб. Минимальный тираж для снижения цены — 500 шт.
A35: 22 | B35: Дегустации для потенциальных клиентов (10–15 баров) | C35: Продажи | D35: 8000 | E35: 15000 | F35: 10000 | H35: Привезти 5–7 пицц на дегустацию в каждый бар. Себестоимость + логистика. Это главный инструмент продаж.
A36: 23 | B36: Маркетинг: визитки, брендинг, Telegram-канал | C36: Маркетинг | D36: 3000 | E36: 7000 | F36: 5000 | H36: Минимум: визитки 500 шт. (~1 500 руб.) + простой логотип + оформление Telegram.
A37: 24 | B37: Первичная логистика: термобоксы, первые доставки | C37: Логистика | D37: 5000 | E37: 10000 | F37: 8000 | H37: 2–3 термобокса для транспортировки замороженной пиццы до подключения рефтранспорта партнёра.
... A39: 26 | B39: Непредвиденные расходы (резерв на мес. 0) | C39: Резерв | D39: 5000 | E39: 15000 | F39: 10000 | H39: Всегда что-то идёт не так при запуске. Лучше иметь и не потратить.
A40: ИТОГО: Предстартовые расходы | D40: =D26+D27+D28+D29+D30+D31+D32+D33+D34+D35+D36+D37+D38+D39 -> 89000 | E40: =E26+E27+E28+E29+E30+E31+E32+E33+E34+E35+E36+E37+E38+E39 -> 222500 | F40: =F26+F27+F28+F29+F30+F31+F32+F33+F34+F35+F36+F37+F38+F39 -> 147000 | G40: =G26+G27+G28+G29+G30+G31+G32+G33+G34+G35+G36+G37+G38+G39 -> 0
A42: ▌ 4. ОБОРОТНЫЙ БУФЕР (резерв на первые месяцы работы)
A43: № | B43: Статья расхода | C43: Категория | D43: Мин, руб. | E43: Макс, руб. | F43: Бюджет, руб. | G43: Факт, руб. | H43: Примечание / источник
A44: 27 | B44: Запас на покрытие кассового разрыва (отсрочка платежей B2B) | C44: Буфер | D44: 20000 | E44: 40000 | F44: 30000 | H44: B2B-клиенты платят с задержкой 14–30 дней. Нужен запас, чтобы не останавливать производство.
A45: 28 | B45: Запас на пополнение ингредиентов (2-й и 3-й месяц) | C45: Буфер | D45: 15000 | E45: 30000 | F45: 20000 | H45: Ингредиенты закупаются до получения оплаты от клиентов. Нужен оборотный капитал.
...
